<sdf version='1.10'>
  <world name='empty'>
    <physics name='1ms' type='ignored'>
      <max_step_size>0.001</max_step_size>
      <real_time_factor>1</real_time_factor>
      <real_time_update_rate>1000</real_time_update_rate>
    </physics>
    <plugin name='gz::sim::systems::Physics' filename='gz-sim-physics-system'/>
    <plugin name='gz::sim::systems::UserCommands' filename='gz-sim-user-commands-system'/>
    <plugin name='gz::sim::systems::SceneBroadcaster' filename='gz-sim-scene-broadcaster-system'/>
    <plugin name='gz::sim::systems::Contact' filename='gz-sim-contact-system'/>
    <gravity>0 0 -9.8000000000000007</gravity>
    <magnetic_field>5.5644999999999998e-06 2.2875799999999999e-05 -4.2388400000000002e-05</magnetic_field>
    <atmosphere type='adiabatic'/>
    <scene>
      <ambient>0.400000006 0.400000006 0.400000006 1</ambient>
      <background>0.699999988 0.699999988 0.699999988 1</background>
      <shadows>true</shadows>
    </scene>
    <model name='ground_plane'>
      <static>true</static>
      <link name='link'>
        <collision name='collision'>
          <geometry>
            <plane>
              <normal>0 0 1</normal>
              <size>100 100</size>
            </plane>
          </geometry>
          <surface>
            <friction>
              <ode/>
            </friction>
            <bounce/>
            <contact/>
          </surface>
        </collision>
        <visual name='visual'>
          <geometry>
            <plane>
              <normal>0 0 1</normal>
              <size>100 100</size>
            </plane>
          </geometry>
          <material>
            <ambient>0.800000012 0.800000012 0.800000012 1</ambient>
            <diffuse>0.800000012 0.800000012 0.800000012 1</diffuse>
            <specular>0.800000012 0.800000012 0.800000012 1</specular>
          </material>
        </visual>
        <pose>0 0 0 0 0 0</pose>
        <inertial>
          <pose>0 0 0 0 0 0</pose>
          <mass>1</mass>
          <inertia>
            <ixx>1</ixx>
            <ixy>0</ixy>
            <ixz>0</ixz>
            <iyy>1</iyy>
            <iyz>0</iyz>
            <izz>1</izz>
          </inertia>
        </inertial>
        <enable_wind>false</enable_wind>
      </link>
      <pose>0 0 0 0 0 0</pose>
      <self_collide>false</self_collide>
    </model>
    <model name='my_robot'>
      <link name='base_footprint'>
        <inertial>
          <pose>0.01785714285714286 0 0.18928571428571431 0 0 0</pose>
          <mass>5.5999999999999996</mass>
          <inertia>
            <ixx>0.097023809523809651</ixx>
            <ixy>0</ixy>
            <ixz>0.013928571428571431</ixz>
            <iyy>0.19857142857142859</iyy>
            <iyz>0</iyz>
            <izz>0.23588095238095241</izz>
          </inertia>
        </inertial>
        <collision name='base_footprint_fixed_joint_lump__base_link_collision'>
          <pose>0 0 0.20000000000000001 0 0 0</pose>
          <geometry>
            <box>
              <size>0.59999999999999998 0.40000000000000002 0.20000000000000001</size>
            </box>
          </geometry>
          <surface>
            <friction>
              <ode/>
            </friction>
            <bounce/>
            <contact/>
          </surface>
        </collision>
        <collision name='base_footprint_fixed_joint_lump__caster_wheel_link_collision_1'>
          <pose>0.20000000000000001 0 0.050000000000000003 0 0 0</pose>
          <geometry>
            <sphere>
              <radius>0.050000000000000003</radius>
            </sphere>
          </geometry>
          <surface>
            <contact>
              <ode/>
            </contact>
            <friction>
              <ode>
                <mu>0.10000000000000001</mu>
                <mu2>0.10000000000000001</mu2>
              </ode>
            </friction>
            <bounce/>
          </surface>
        </collision>
        <collision name='base_footprint_fixed_joint_lump__lidar_link_collision_2'>
          <pose>0 0 0.34999999999999998 0 0 0</pose>
          <geometry>
            <cylinder>
              <length>0.10000000000000001</length>
              <radius>0.10000000000000001</radius>
            </cylinder>
          </geometry>
          <surface>
            <contact>
              <ode/>
            </contact>
            <friction>
              <ode/>
            </friction>
            <bounce/>
          </surface>
        </collision>
        <visual name='base_footprint_fixed_joint_lump__base_link_visual'>
          <pose>0 0 0.20000000000000001 0 0 0</pose>
          <geometry>
            <box>
              <size>0.59999999999999998 0.40000000000000002 0.20000000000000001</size>
            </box>
          </geometry>
          <material>
            <diffuse>0 0 0.625 1</diffuse>
            <ambient>0 0 0.625 1</ambient>
          </material>
        </visual>
        <visual name='base_footprint_fixed_joint_lump__caster_wheel_link_visual_1'>
          <pose>0.20000000000000001 0 0.050000000000000003 0 0 0</pose>
          <geometry>
            <sphere>
              <radius>0.050000000000000003</radius>
            </sphere>
          </geometry>
          <material>
            <diffuse>0.625 0.625 0.625 1</diffuse>
            <ambient>0.625 0.625 0.625 1</ambient>
          </material>
        </visual>
        <visual name='base_footprint_fixed_joint_lump__lidar_link_visual_2'>
          <pose>0 0 0.34999999999999998 0 0 0</pose>
          <geometry>
            <cylinder>
              <length>0.10000000000000001</length>
              <radius>0.10000000000000001</radius>
            </cylinder>
          </geometry>
          <material>
            <diffuse>1 0 0 1</diffuse>
            <ambient>1 0 0 1</ambient>
          </material>
        </visual>
        <sensor name='gpu_lidar' type='gpu_lidar'>
          <pose>0 0 0.34999999999999998 0 0 0</pose>
          <topic>scan</topic>
          <update_rate>2</update_rate>
          <enable_metrics>false</enable_metrics>
          <lidar>
            <scan>
              <horizontal>
                <samples>720</samples>
                <resolution>1</resolution>
                <min_angle>-3.1400000000000001</min_angle>
                <max_angle>3.1400000000000001</max_angle>
              </horizontal>
              <vertical>
                <samples>1</samples>
                <min_angle>0</min_angle>
                <max_angle>0</max_angle>
                <resolution>1</resolution>
              </vertical>
            </scan>
            <range>
              <min>0.01</min>
              <max>12</max>
              <resolution>0.0050000000000000001</resolution>
            </range>
            <noise>
              <type>gaussian</type>
              <mean>0</mean>
              <stddev>0.001</stddev>
            </noise>
            <visibility_mask>4294967295</visibility_mask>
          </lidar>
        </sensor>
        <pose>0 0 0 0 0 0</pose>
        <enable_wind>false</enable_wind>
      </link>
      <joint name='base_left_wheel_joint' type='revolute'>
        <pose>0 0 0 0 0 0</pose>
        <parent>base_footprint</parent>
        <child>left_wheel_link</child>
        <axis>
          <xyz>0 1 0</xyz>
          <limit>
            <lower>-inf</lower>
            <upper>inf</upper>
            <effort>inf</effort>
            <velocity>inf</velocity>
            <stiffness>100000000</stiffness>
            <dissipation>1</dissipation>
          </limit>
          <dynamics>
            <spring_reference>0</spring_reference>
            <spring_stiffness>0</spring_stiffness>
            <damping>0</damping>
            <friction>0</friction>
          </dynamics>
        </axis>
      </joint>
      <link name='left_wheel_link'>
        <pose>-0.14999999999999999 0.22500000000000001 0.099999999999999992 -1.8449430334025024e-38 1.863984246600538e-15 -1.7194723750688375e-53</pose>
        <inertial>
          <pose>0 0 0 1.5707963267948959 0 0</pose>
          <mass>1</mass>
          <inertia>
            <ixx>0.0027083333333333339</ixx>
            <ixy>0</ixy>
            <ixz>0</ixz>
            <iyy>0.0027083333333333339</iyy>
            <iyz>0</iyz>
            <izz>0.005000000000000001</izz>
          </inertia>
        </inertial>
        <collision name='left_wheel_link_collision'>
          <pose>0 0 0 0 0 0</pose>
          <geometry>
            <sphere>
              <radius>0.10000000000000001</radius>
            </sphere>
          </geometry>
          <surface>
            <friction>
              <ode/>
            </friction>
            <bounce/>
            <contact/>
          </surface>
        </collision>
        <visual name='left_wheel_link_visual'>
          <pose>0 0 0 1.5707963267948959 0 0</pose>
          <geometry>
            <cylinder>
              <length>0.050000000000000003</length>
              <radius>0.10000000000000001</radius>
            </cylinder>
          </geometry>
          <material>
            <diffuse>0.625 0.625 0.625 1</diffuse>
            <ambient>0.625 0.625 0.625 1</ambient>
          </material>
        </visual>
        <enable_wind>false</enable_wind>
      </link>
      <joint name='base_right_wheel_joint' type='revolute'>
        <pose>0 0 0 0 0 0</pose>
        <parent>base_footprint</parent>
        <child>right_wheel_link</child>
        <axis>
          <xyz>0 1 0</xyz>
          <limit>
            <lower>-inf</lower>
            <upper>inf</upper>
            <effort>inf</effort>
            <velocity>inf</velocity>
            <stiffness>100000000</stiffness>
            <dissipation>1</dissipation>
          </limit>
          <dynamics>
            <spring_reference>0</spring_reference>
            <spring_stiffness>0</spring_stiffness>
            <damping>0</damping>
            <friction>0</friction>
          </dynamics>
        </axis>
      </joint>
      <link name='right_wheel_link'>
        <pose>-0.14999999999999999 -0.22500000000000001 0.099999999999999992 -1.8449497900832668e-38 1.8639835041348524e-15 -1.7194779873361339e-53</pose>
        <inertial>
          <pose>0 0 0 1.5707963267948959 0 0</pose>
          <mass>1</mass>
          <inertia>
            <ixx>0.0027083333333333339</ixx>
            <ixy>0</ixy>
            <ixz>0</ixz>
            <iyy>0.0027083333333333339</iyy>
            <iyz>0</iyz>
            <izz>0.005000000000000001</izz>
          </inertia>
        </inertial>
        <collision name='right_wheel_link_collision'>
          <pose>0 0 0 0 0 0</pose>
          <geometry>
            <sphere>
              <radius>0.10000000000000001</radius>
            </sphere>
          </geometry>
          <surface>
            <friction>
              <ode/>
            </friction>
            <bounce/>
            <contact/>
          </surface>
        </collision>
        <visual name='right_wheel_link_visual'>
          <pose>0 0 0 1.5707963267948959 0 0</pose>
          <geometry>
            <cylinder>
              <length>0.050000000000000003</length>
              <radius>0.10000000000000001</radius>
            </cylinder>
          </geometry>
          <material>
            <diffuse>0.625 0.625 0.625 1</diffuse>
            <ambient>0.625 0.625 0.625 1</ambient>
          </material>
        </visual>
        <enable_wind>false</enable_wind>
      </link>
      <plugin name='gz::sim::systems::DiffDrive' filename='gz-sim-diff-drive-system'>
        <left_joint>base_left_wheel_joint</left_joint>
        <right_joint>base_right_wheel_joint</right_joint>
        <wheel_separation>0.45</wheel_separation>
        <wheel_radius>0.1</wheel_radius>
        <frame_id>odom</frame_id>
        <child_frame_id>base_footprint</child_frame_id>
      </plugin>
      <plugin name='gz::sim::systems::JointStatePublisher' filename='gz-sim-joint-state-publisher-system'>
        <joint_name>base_left_wheel_joint</joint_name>
        <joint_name>base_right_wheel_joint</joint_name>
      </plugin>
      <plugin name='gz::sim::systems::Sensors' filename='gz-sim-sensors-system'>
        <render_engine>ogre2</render_engine>
      </plugin>
      <frame name='base_caster_wheel_joint' attached_to='base_link'>
        <pose>0.20000000000000001 0 -0.050000000000000003 0 0 0</pose>
      </frame>
      <frame name='caster_wheel_link' attached_to='base_caster_wheel_joint'>
        <pose>0 0 0 0 0 0</pose>
      </frame>
      <frame name='laser_joint' attached_to='base_link'>
        <pose>0 0 0.25 0 0 0</pose>
      </frame>
      <frame name='lidar_link' attached_to='laser_joint'>
        <pose>0 0 0 0 0 0</pose>
      </frame>
      <frame name='base_joint' attached_to='base_footprint'>
        <pose>0 0 0.10000000000000001 0 0 0</pose>
      </frame>
      <frame name='base_link' attached_to='base_joint'>
        <pose>0 0 0 0 0 0</pose>
      </frame>
      <pose>1.3824509592641478e-16 -3.1527812907799656e-22 -9.66049827477028e-11 1.0971589275272564e-21 -4.2228893779375221e-11 1.8200761735406916e-22</pose>
      <static>false</static>
      <self_collide>false</self_collide>
    </model>
    <model name='sphere'>
      <pose>2.3899406051344823 0.21506505314569693 0.499999999902001 0 0 0</pose>
      <link name='sphere_link'>
        <inertial>
          <inertia>
            <ixx>0.10000000000000001</ixx>
            <ixy>0</ixy>
            <ixz>0</ixz>
            <iyy>0.10000000000000001</iyy>
            <iyz>0</iyz>
            <izz>0.10000000000000001</izz>
          </inertia>
          <mass>1</mass>
          <pose>0 0 0 0 0 0</pose>
        </inertial>
        <collision name='sphere_collision'>
          <geometry>
            <sphere>
              <radius>0.5</radius>
            </sphere>
          </geometry>
          <surface>
            <friction>
              <ode/>
            </friction>
            <bounce/>
            <contact/>
          </surface>
        </collision>
        <visual name='sphere_visual'>
          <geometry>
            <sphere>
              <radius>0.5</radius>
            </sphere>
          </geometry>
          <material>
            <ambient>0.300000012 0.300000012 0.300000012 1</ambient>
            <diffuse>0.699999988 0.699999988 0.699999988 1</diffuse>
            <specular>1 1 1 1</specular>
          </material>
        </visual>
        <pose>0 0 0 0 0 0</pose>
        <enable_wind>false</enable_wind>
      </link>
      <static>false</static>
      <self_collide>false</self_collide>
    </model>
    <model name='box'>
      <pose>0.96101051790478387 3.0934815292030007 0.49999999990199806 6.2287739151293738e-22 9.3279666454713669e-22 -3.6315533669320137e-22</pose>
      <link name='box_link'>
        <inertial>
          <inertia>
            <ixx>0.16666</ixx>
            <ixy>0</ixy>
            <ixz>0</ixz>
            <iyy>0.16666</iyy>
            <iyz>0</iyz>
            <izz>0.16666</izz>
          </inertia>
          <mass>1</mass>
          <pose>0 0 0 0 0 0</pose>
        </inertial>
        <collision name='box_collision'>
          <geometry>
            <box>
              <size>1 1 1</size>
            </box>
          </geometry>
          <surface>
            <friction>
              <ode/>
            </friction>
            <bounce/>
            <contact/>
          </surface>
        </collision>
        <visual name='box_visual'>
          <geometry>
            <box>
              <size>1 1 1</size>
            </box>
          </geometry>
          <material>
            <ambient>0.300000012 0.300000012 0.300000012 1</ambient>
            <diffuse>0.699999988 0.699999988 0.699999988 1</diffuse>
            <specular>1 1 1 1</specular>
          </material>
        </visual>
        <pose>0 0 0 0 0 0</pose>
        <enable_wind>false</enable_wind>
      </link>
      <static>false</static>
      <self_collide>false</self_collide>
    </model>
    <model name='cylinder'>
      <pose>-0.15574550892134642 -2.4490957105495745 0.49999942638036005 3.1933137519272363e-20 1.0168291615426776e-19 1.5769117218365828e-21</pose>
      <link name='cylinder_link'>
        <inertial>
          <inertia>
            <ixx>0.14580000000000001</ixx>
            <ixy>0</ixy>
            <ixz>0</ixz>
            <iyy>0.14580000000000001</iyy>
            <iyz>0</iyz>
            <izz>0.125</izz>
          </inertia>
          <mass>1</mass>
          <pose>0 0 0 0 0 0</pose>
        </inertial>
        <collision name='cylinder_collision'>
          <geometry>
            <cylinder>
              <radius>0.5</radius>
              <length>1</length>
            </cylinder>
          </geometry>
          <surface>
            <friction>
              <ode/>
            </friction>
            <bounce/>
            <contact/>
          </surface>
        </collision>
        <visual name='cylinder_visual'>
          <geometry>
            <cylinder>
              <radius>0.5</radius>
              <length>1</length>
            </cylinder>
          </geometry>
          <material>
            <ambient>0.300000012 0.300000012 0.300000012 1</ambient>
            <diffuse>0.699999988 0.699999988 0.699999988 1</diffuse>
            <specular>1 1 1 1</specular>
          </material>
        </visual>
        <pose>0 0 0 0 0 0</pose>
        <enable_wind>false</enable_wind>
      </link>
      <static>false</static>
      <self_collide>false</self_collide>
    </model>
    <model name='cone'>
      <pose>-1.1318177106358935 1.7040653362394451 0.49999999993296756 5.2539673238603227e-17 -7.7132841034849224e-10 -2.2042306062451038e-22</pose>
      <link name='cone_link'>
        <inertial>
          <inertia>
            <ixx>0.074999999999999997</ixx>
            <ixy>0</ixy>
            <ixz>0</ixz>
            <iyy>0.074999999999999997</iyy>
            <iyz>0</iyz>
            <izz>0.074999999999999997</izz>
          </inertia>
          <mass>1</mass>
          <pose>0 0 0 0 0 0</pose>
        </inertial>
        <collision name='cone_collision'>
          <geometry>
            <cone>
              <radius>0.5</radius>
              <length>1</length>
            </cone>
          </geometry>
          <surface>
            <friction>
              <ode/>
            </friction>
            <bounce/>
            <contact/>
          </surface>
        </collision>
        <visual name='cone_visual'>
          <geometry>
            <cone>
              <radius>0.5</radius>
              <length>1</length>
            </cone>
          </geometry>
          <material>
            <ambient>0.300000012 0.300000012 0.300000012 1</ambient>
            <diffuse>0.699999988 0.699999988 0.699999988 1</diffuse>
            <specular>1 1 1 1</specular>
          </material>
        </visual>
        <pose>0 0 0 0 0 0</pose>
        <enable_wind>false</enable_wind>
      </link>
      <static>false</static>
      <self_collide>false</self_collide>
    </model>
    <light name='sun' type='directional'>
      <pose>0 0 10 0 0 0</pose>
      <cast_shadows>true</cast_shadows>
      <intensity>1</intensity>
      <direction>-0.5 0.10000000000000001 -0.90000000000000002</direction>
      <diffuse>0.800000012 0.800000012 0.800000012 1</diffuse>
      <specular>0.200000003 0.200000003 0.200000003 1</specular>
      <attenuation>
        <range>1000</range>
        <linear>0.01</linear>
        <constant>0.90000000000000002</constant>
        <quadratic>0.001</quadratic>
      </attenuation>
      <spot>
        <inner_angle>0</inner_angle>
        <outer_angle>0</outer_angle>
        <falloff>0</falloff>
      </spot>
    </light>
  </world>
</sdf>
